Workbook

Sheet README
B2: RetailQE - Test Case List & Requirements Traceability Matrix
B3: Lewis Retail Group - Retail Delivery Module (Quality Engineering Capstone)
B5: Sheets in this workbook
B6: Test Cases | C6: All 100 layer tests (40 Cypress, 40 Postman, 20 SQL) plus the 5 E2E scenarios, with IDs in the T-LAYER-FEATURE-### format.
B7: E2E Steps | C7: Step-by-step detail for the 5 end-to-end scenarios (each step is tagged UI, API or SQL and mapped to acceptance criteria).
B8: RTM | C8: Requirements Traceability Matrix: every acceptance criterion of FR-001 to FR-007 mapped to its tests. Counts, coverage and results are formulas that read from 'Test Cases'.
B9: Coverage Summary | C9: Counts per layer and feature against the brief's targets, pass rates against the exit criteria, and FR/AC coverage. All formulas.
B11: What to edit (yellow columns on 'Test Cases')
B12: Automation Status | C12: Planned / In Progress / Automated / Manual (drop-down).
B13: Execution Status | C13: Not Run / Pass / Fail / Blocked / Skipped (drop-down). The RTM and Coverage Summary update automatically from this column.
B14: Executed By / Date | C14: Tester name and run date, e.g. 'Uzair' and 2026-11-03.
B15: Defect ID | C15: JIRA defect key, e.g. RQE-42. Separate several with a semicolon. Copy the IDs into the RTM 'Defect IDs' column as well.
B16: Evidence Link | C16: Path or link to the proof, e.g. reports/cypress/T-UI-PAY-001.png or a JIRA attachment link.
B17: JIRA Story | C17: Story/epic key the test traces to, e.g. RQE-7.
B18: RTM (yellow columns) | C18: Defect IDs and JIRA Story/Epic for each acceptance criterion. Everything else on the RTM is calculated.
B20: Assumptions and things to confirm
B21: Written before the SUT | C21: These tests were written from the capstone brief only; the application, API and database have not been seen yet. Selectors, endpoints, status codes, table names and error messages are provisional and should be confirmed against the real system and its Swagger docs.
B22: Table names | C22: SQL tests use generic table names (Orders, OrderItems, Payments, Refunds, Shipments, Inventory, InventoryLedger, AuditLog, NotificationLog, ProofOfDelivery). Rename to match the real schema.
B23: E2E step count | C23: The brief says E2E scenarios need >=10 steps each, but lists 'Payment Failure & Retry' as 5 steps. All 5 scenarios here have 11-13 steps; the 5-step core of the payment scenario is steps 2-6.
B24: Counts | C24: The brief says 100 tests 'excluding E2E steps'. The 5 E2E scenarios are counted separately, so the workbook has 105 rows.
B25: FR-006 at API level | C25: Section 2.2 has no Dashboard API category, so FR-006 is covered by API-ORD-010 (history, pagination, filters) and API-ERR-004 (profile and saved addresses). Move ERR-004 into its own folder if your facilitator prefers.
B26: Cross-browser | C26: Cypress supports Chrome, Firefox and Edge. Cross-browser tests T-UI-XBR-001 to 003 re-run the login flow; 004-005 re-run the totals flow; 006 checks two desktop resolutions.
B27: Session expiry | C27: T-UI-AUTH-004 uses cy.clock. If the app enforces expiry only on the server, shorten the token lifetime in the test environment instead.
B28: Out of scope | C28: Performance, security penetration, mobile apps, building the retail system and DevOps are excluded per the brief.
B30: Colour key
B31: Yellow header/cell | C31: Cells for you to fill in.
B32: Blue text | C32: Cells for you to fill in (yellow fill). Blue text = fixed targets taken from the brief on the Coverage Summary sheet.

Sheet Test Cases
A1: Test ID | B1: Layer | C1: Feature | D1: FR Ref | E1: AC Ref(s) | F1: Priority | G1: Type | H1: Test Title | I1: Preconditions | J1: Test Steps | K1: Test Data | L1: Expected Result | M1: Tool / Location | N1: Automation Status | O1: Execution Status | P1: Executed By | Q1: Execution Date | R1: Defect ID | S1: Evidence Link | T1: JIRA Story
A2: T-UI-AUTH-001 | B2: Cypress (UI) | C2: User Authentication | D2: FR-001 | E2: FR-001-AC1 | F2: P0 | G2: Positive | H2: User login with valid email and password succeeds | I2: Active test customer account exists; app reachable; browser on login page | J2: 1. Open the login page 2. Enter a valid email and password 3. Click Login | K2: validUser in fixtures/users.json | L2: User is redirected to the dashboard; user name is displayed; session cookie/token is set | M2: cypress/e2e/auth.cy.js | N2: Planned | O2: Not Run
A3: T-UI-AUTH-002 | B3: Cypress (UI) | C3: User Authentication | D3: FR-001 | E3: FR-001-AC2 | F3: P0 | G3: Negative | H3: Login with invalid credentials is rejected with a clear error message | I3: Active test customer account exists; app reachable; browser on login page | J3: 1. Open the login page 2. Enter a valid email with a wrong password and click Login 3. Repeat with an unregistered email 4. Repeat with an empty password | K3: invalidUsers[] in fixtures/users.json | L3: Login is rejected each time; a clear, non-technical error is shown; user stays on the login page; no session is created; the message does not reveal which field was wrong | M3: cypress/e2e/auth.cy.ts | N3: Planned | O3: Not Run
A4: T-UI-AUTH-003 | B4: Cypress (UI) | C4: User Authentication | D4: FR-001 | E4: FR-001-AC3 | F4: P0 | G4: Positive | H4: Session persists across page navigation | I4: Active test customer account exists; app reachable; browser on login page | J4: 1. Log in 2. Navigate Dashboard > Orders > Tracking 3. Refresh the browser on each page | L4: User stays authenticated on every page and after refresh; no re-login prompt | M4: cypress/e2e/auth.cy.js | N4: Planned | O4: Not Run
A5: T-UI-AUTH-004 | B5: Cypress (UI) | C5: User Authentication | D5: FR-001 | E5: FR-001-AC4 | F5: P0 | G5: Boundary | H5: Session expires after 30 minutes of inactivity | I5: Active test customer account exists; app reachable; browser on login page | J5: 1. Log in 2. Advance the clock 29 minutes (cy.clock/cy.tick) and perform an action 3. Advance a further 2 minutes with no activity and perform an action | K5: If the server enforces expiry, use a short-lived token via test config instead of cy.clock | L5: At 29 minutes the session is still valid; after 30+ minutes the user is redirected to login with a session-expired message and protected pages are inaccessible | M5: cypress/e2e/auth.cy.ts | N5: Planned | O5: Not Run
A6: T-UI-ORD-001 | B6: Cypress (UI) | C6: Order Management | D6: FR-002 | E6: FR-002-AC1 | F6: P0 | G6: Positive | H6: Add a product to the order with a valid quantity | I6: Logged-in customer; catalogue seeded with in-stock SKUs at known prices; tax rate known | J6: 1. Search for an in-stock product 2. Set quantity to 2 3. Click Add to cart 4. Open the cart | K6: SKU-001 qty 2 | L6: Cart shows the product with quantity 2, unit price and the correct line subtotal | M6: cypress/e2e/orders.cy.ts | N6: Planned | O6: Not Run
A7: T-UI-ORD-002 | B7: Cypress (UI) | C7: Order Management | D7: FR-002 | E7: FR-002-AC1 | F7: P0 | G7: Negative / Boundary | H7: Quantity validation rejects zero, negative, non-numeric and above-stock quantities | I7: Logged-in customer; catalogue seeded with in-stock SKUs at known prices; tax rate known | J7: 1. Enter quantity 0 2. Enter -1 3. Enter 'abc' 4. Enter stock + 1 5. Enter exactly the available stock | K7: Product with known stock level | L7: 0, -1, 'abc' and stock + 1 are rejected with a validation message and the cart is unchanged; quantity equal to available stock is accepted | M7: cypress/e2e/orders.cy.ts | N7: Planned | O7: Not Run
A8: T-UI-ORD-003 | B8: Cypress (UI) | C8: Order Management | D8: FR-002 | E8: FR-002-AC2 | F8: P0 | G8: Positive | H8: Order total equals items x price + tax | I8: Logged-in customer; catalogue seeded with in-stock SKUs at known prices; tax rate known | J8: 1. Add two different products with different quantities 2. Read the displayed subtotal, tax and total | K8: SKU-001 x2, SKU-002 x3 | L8: Total = SUM(qty x unit price) + tax, rounded to 2 decimals, and matches the value calculated independently from fixtures | M8: cypress/e2e/orders.cy.ts | N8: Planned | O8: Not Run
A9: T-UI-ORD-004 | B9: Cypress (UI) | C9: Order Management | D9: FR-002 | E9: FR-002-AC3 | F9: P0 | G9: Positive | H9: Valid coupon code applies the correct discount | I9: Logged-in customer; catalogue seeded with in-stock SKUs at known prices; tax rate known | J9: 1. Add products to the cart 2. Enter a valid coupon code 3. Click Apply | K9: coupons.valid in fixtures | L9: Discount line is displayed; total is reduced by the correct amount/percentage; tax is recalculated per business rule | M9: cypress/e2e/orders.cy.ts | N9: Planned | O9: Not Run
A10: T-UI-ORD-005 | B10: Cypress (UI) | C10: Order Management | D10: FR-002 | E10: FR-002-AC3 | F10: P0 | G10: Negative | H10: Invalid, expired or already-used coupon is rejected | I10: Logged-in customer; catalogue seeded with in-stock SKUs at known prices; tax rate known | J10: 1. Add products to the cart 2. Apply an invalid code 3. Apply an expired code 4. Apply a single-use code that was already redeemed | K10: coupons.invalid / expired / used | L10: Each coupon is rejected with a clear message; order total is unchanged | M10: cypress/e2e/orders.cy.ts | N10: Planned | O10: Not Run
A11: T-UI-ORD-006 | B11: Cypress (UI) | C11: Order Management | D11: FR-002 | E11: FR-002-AC4 | F11: P0 | G11: Positive | H11: Order quantity can be modified before payment and totals recalculate | I11: Logged-in customer; catalogue seeded with in-stock SKUs at known prices; tax rate known | J11: 1. Create an unpaid order 2. Change a line quantity from 2 to 4 3. Save | L11: Line subtotal, tax and order total are recalculated correctly and persisted after refresh | M11: cypress/e2e/orders.cy.ts | N11: Planned | O11: Not Run
A12: T-UI-ORD-007 | B12: Cypress (UI) | C12: Order Management | D12: FR-002 | E12: FR-002-AC4 | F12: P0 | G12: Positive | H12: Delivery address can be changed before payment | I12: Logged-in customer; catalogue seeded with in-stock SKUs at known prices; tax rate known | J12: 1. Create an unpaid order 2. Edit the delivery address to another saved address 3. Save | L12: New address is shown on the order summary and persists after refresh | M12: cypress/e2e/orders.cy.ts | N12: Planned | O12: Not Run
A13: T-UI-ORD-008 | B13: Cypress (UI) | C13: Order Management | D13: FR-002 | E13: FR-002-AC5 | F13: P0 | G13: Negative | H13: Order cannot be modified after payment | I13: Logged-in customer; catalogue seeded with in-stock SKUs at known prices; tax rate known | J13: 1. Open a paid order 2. Look for edit quantity/address controls 3. Attempt to open the edit URL directly | L13: Edit controls are hidden or disabled; direct URL access is blocked with a message; order data is unchanged | M13: cypress/e2e/orders.cy.ts | N13: Planned | O13: Not Run
A14: T-UI-ORD-009 | B14: Cypress (UI) | C14: Order Management | D14: FR-002 | E14: FR-002-AC6 | F14: P0 | G14: Positive | H14: Cancelling an order updates its status and returns inventory | I14: Logged-in customer; catalogue seeded with in-stock SKUs at known prices; tax rate known | J14: 1. Note the product's available stock 2. Create and cancel an order for quantity 2 3. Re-open the product page | L14: Order status shows Cancelled; displayed available stock is restored to the original level | M14: cypress/e2e/orders.cy.ts | N14: Planned | O14: Not Run
A15: T-UI-ORD-010 | B15: Cypress (UI) | C15: Order Management | D15: FR-002 | E15: FR-002-AC7 | F15: P0 | G15: Negative | H15: Rapid double submission creates only one order | I15: Logged-in customer; catalogue seeded with in-stock SKUs at known prices; tax rate known | J15: 1. Prepare a valid cart 2. Double-click Place Order (or submit twice within 1 second) 3. Open order history | L15: Only one order is created; the second submission is ignored or returns the same order | M15: cypress/e2e/orders.cy.ts | N15: Planned | O15: Not Run
A16: T-UI-PAY-001 | B16: Cypress (UI) | C16: Payment Processing | D16: FR-003 | E16: FR-003-AC2 | F16: P0 | G16: Positive | H16: Payment with a valid card succeeds | I16: Logged-in customer with an order awaiting payment; payment sandbox test cards available | J16: 1. Open payment for an unpaid order 2. Enter a valid sandbox card, expiry and CVV 3. Click Pay | K16: cards.valid in fixtures | L16: Payment is confirmed; order status changes to Paid; confirmation/receipt is displayed | M16: cypress/e2e/payments.cy.ts | N16: Planned | O16: Not Run
A17: T-UI-PAY-002 | B17: Cypress (UI) | C17: Payment Processing | D17: FR-003 | E17: FR-003-AC1 | F17: P0 | G17: Negative | H17: Invalid card number format is rejected | I17: Logged-in customer with an order awaiting payment; payment sandbox test cards available | J17: 1. Enter a card number with letters 2. Enter a too-short number 3. Enter a 16-digit number that fails the Luhn check | K17: cards.badNumber[] | L17: Each entry is rejected with an inline validation message; Pay does not submit; no charge is attempted | M17: cypress/e2e/payments.cy.ts | N17: Planned | O17: Not Run
A18: T-UI-PAY-003 | B18: Cypress (UI) | C18: Payment Processing | D18: FR-003 | E18: FR-003-AC1 | F18: P0 | G18: Boundary | H18: Expired card is rejected | I18: Logged-in customer with an order awaiting payment; payment sandbox test cards available | J18: 1. Enter a valid number with an expiry in the previous month 2. Enter the current month and year | K18: cards.expired | L18: Previous month is rejected with an expiry message; current month is accepted | M18: cypress/e2e/payments.cy.ts | N18: Planned | O18: Not Run
A19: T-UI-PAY-004 | B19: Cypress (UI) | C19: Payment Processing | D19: FR-003 | E19: FR-003-AC1 | F19: P0 | G19: Negative | H19: Invalid CVV is rejected | I19: Logged-in customer with an order awaiting payment; payment sandbox test cards available | J19: 1. Enter a valid card with a 2-digit CVV 2. Enter non-numeric CVV 3. Leave CVV empty | L19: Each CVV is rejected with a clear validation message; payment is not submitted | M19: cypress/e2e/payments.cy.ts | N19: Planned | O19: Not Run
A20: T-UI-PAY-005 | B20: Cypress (UI) | C20: Payment Processing | D20: FR-003 | E20: FR-003-AC3 | F20: P0 | G20: Negative | H20: Declined card is handled gracefully | I20: Logged-in customer with an order awaiting payment; payment sandbox test cards available | J20: 1. Pay with the sandbox 'decline' test card 2. Observe the result 3. Open the order | K20: cards.declined | L20: A friendly decline message is shown (no technical error/stack trace); order remains unpaid; user can retry | M20: cypress/e2e/payments.cy.ts | N20: Planned | O20: Not Run
A21: T-UI-PAY-006 | B21: Cypress (UI) | C21: Payment Processing | D21: FR-003 | E21: FR-003-AC4 | F21: P0 | G21: Negative | H21: Double-clicking Pay does not charge twice | I21: Logged-in customer with an order awaiting payment; payment sandbox test cards available | J21: 1. Enter valid card details 2. Double-click Pay 3. Check order and payment status | L21: Only one payment is processed; Pay button is disabled after the first click; order shows a single payment | M21: cypress/e2e/payments.cy.ts | N21: Planned | O21: Not Run
A22: T-UI-DEL-001 | B22: Cypress (UI) | C22: Delivery Tracking | D22: FR-004 | E22: FR-004-AC2 | F22: P0 | G22: Positive | H22: Tracking number is assigned and visible on the order details page | I22: Paid orders exist in Shipped and Delivered states; one paid order not yet shipped; one unpaid order | J22: 1. Open a shipped order 2. View the delivery section | L22: A tracking number is displayed and matches the format and value in the API response | M22: cypress/e2e/delivery.cy.ts | N22: Planned | O22: Not Run
A23: T-UI-DEL-002 | B23: Cypress (UI) | C23: Delivery Tracking | D23: FR-004 | E23: FR-004-AC3 | F23: P0 | G23: Positive | H23: Shipped status is displayed correctly | I23: Paid orders exist in Shipped and Delivered states; one paid order not yet shipped; one unpaid order | J23: 1. Open an order whose shipment is Shipped 2. Check the status and tracking timeline | L23: Status shows Shipped with a timestamp; timeline lists earlier steps in order | M23: cypress/e2e/delivery.cy.ts | N23: Planned | O23: Not Run
A24: T-UI-DEL-003 | B24: Cypress (UI) | C24: Delivery Tracking | D24: FR-004 | E24: FR-004-AC3 | F24: P0 | G24: Positive | H24: Delivered status is displayed after the shipment is delivered | I24: Paid orders exist in Shipped and Delivered states; one paid order not yet shipped; one unpaid order | J24: 1. Open an order whose shipment is Delivered 2. Check the status and timeline | L24: Status shows Delivered with a timestamp; timeline shows Shipped before Delivered | M24: cypress/e2e/delivery.cy.ts | N24: Planned | O24: Not Run
A25: T-UI-DEL-004 | B25: Cypress (UI) | C25: Delivery Tracking | D25: FR-004 | E25: FR-004-AC1 | F25: P0 | G25: Negative | H25: Unpaid order shows no shipment or tracking number | I25: Paid orders exist in Shipped and Delivered states; one paid order not yet shipped; one unpaid order | J25: 1. Open an unpaid order 2. View the delivery section | L25: No shipment is created or shown and no tracking number is displayed; status reflects awaiting payment | M25: cypress/e2e/delivery.cy.ts | N25: Planned | O25: Not Run
A26: T-UI-DEL-005 | B26: Cypress (UI) | C26: Delivery Tracking | D26: FR-004 | E26: FR-004-AC2 | F26: P0 | G26: Positive / Negative | H26: Tracking page finds a shipment by tracking number and handles unknown numbers | I26: Paid orders exist in Shipped and Delivered states; one paid order not yet shipped; one unpaid order | J26: 1. Open the tracking page 2. Enter a valid tracking number 3. Enter an unknown tracking number | L26: Valid number shows shipment status and history; unknown number shows a clear 'not found' message | M26: cypress/e2e/delivery.cy.ts | N26: Planned | O26: Not Run
A27: T-UI-DEL-006 | B27: Cypress (UI) | C27: Delivery Tracking | D27: FR-004 | E27: FR-004-AC5 | F27: P0 | G27: Positive | H27: Proof of delivery is visible on a delivered order | I27: Paid orders exist in Shipped and Delivered states; one paid order not yet shipped; one unpaid order | J27: 1. Open a delivered order 2. View the proof of delivery section | L27: POD details (received-by/signature or photo reference and timestamp) are displayed | M27: cypress/e2e/delivery.cy.ts | N27: Planned | O27: Not Run
A28: T-UI-DASH-001 | B28: Cypress (UI) | C28: User Dashboard | D28: FR-006 | E28: FR-006-AC1 | F28: P1 | G28: Positive | H28: Order history is displayed with pagination | I28: Logged-in customer with 25+ historical orders of mixed status, date and price | J28: 1. Open the dashboard order history 2. Note the page size and total 3. Go to next, previous and last pages | L28: Page size is respected; no order is duplicated or missing across pages; page controls are enabled/disabled correctly at the first and last page | M28: cypress/e2e/dashboard.cy.ts | N28: Planned | O28: Not Run
A29: T-UI-DASH-002 | B29: Cypress (UI) | C29: User Dashboard | D29: FR-006 | E29: FR-006-AC2 | F29: P1 | G29: Positive | H29: Order history can be filtered by date range, status and price | I29: Logged-in customer with 25+ historical orders of mixed status, date and price | J29: 1. Filter by a date range 2. Filter by status 3. Filter by price range 4. Combine filters 5. Clear filters | L29: Only matching orders are shown for each filter and for combinations; counts are correct; clearing restores the full list | M29: cypress/e2e/dashboard.cy.ts | N29: Planned | O29: Not Run
A30: T-UI-DASH-003 | B30: Cypress (UI) | C30: User Dashboard | D30: FR-006 | E30: FR-006-AC3 | F30: P1 | G30: Positive | H30: Saved addresses can be added, edited and deleted | I30: Logged-in customer with 25+ historical orders of mixed status, date and price | J30: 1. Add a new address 2. Edit it 3. Delete it 4. Try saving an address with a missing mandatory field | L30: Add/edit/delete reflect immediately and persist after refresh; missing mandatory field is rejected with a message | M30: cypress/e2e/dashboard.cy.ts | N30: Planned | O30: Not Run
A31: T-UI-DASH-004 | B31: Cypress (UI) | C31: User Dashboard | D31: FR-006 | E31: FR-006-AC4 | F31: P1 | G31: Positive / Negative | H31: Profile name, email and phone can be updated and are validated | I31: Logged-in customer with 25+ historical orders of mixed status, date and price | J31: 1. Update name, email and phone with valid values and save 2. Enter an invalid email 3. Enter an invalid phone number | L31: Valid changes persist after refresh; invalid email and phone are rejected with clear messages | M31: cypress/e2e/dashboard.cy.ts | N31: Planned | O31: Not Run
A32: T-UI-RET-001 | B32: Cypress (UI) | C32: Returns & Refunds | D32: FR-005 | E32: FR-005-AC1 | F32: P1 | G32: Positive | H32: Return can be initiated within the 30-day window | I32: Customer has a delivered order inside the 30-day window and one outside it | J32: 1. Open a delivered order inside 30 days 2. Click Return 3. Select item(s) and reason 4. Submit | L32: Return request is created with status Requested and a return reference is displayed | M32: cypress/e2e/returns.cy.ts | N32: Planned | O32: Not Run
... A41: T-UI-XBR-006 | B41: Cypress (UI) | C41: Cross-Browser Support | D41: FR-004 | E41: FR-004-AC2; FR-004-AC3 | F41: P2 | G41: Positive | H41: Tracking page renders correctly at 1920x1080 and 1366x768 | I41: Same seeded data as the main suite; run with --browser chrome / firefox / edge | J41: 1. Set the viewport to 1920x1080 and open a shipped order 2. Repeat at 1366x768 | L41: Tracking number and status timeline are visible, readable and not truncated at both resolutions | M41: cypress/e2e/cross-browser.cy.ts | N41: Planned | O41: Not Run
A42: T-API-AUTH-001 | B42: Postman (API) | C42: Authentication APIs | D42: FR-001 | E42: FR-001-AC1; FR-001-AC3 | F42: P0 | G42: Positive | H42: POST /auth/login with valid credentials returns 200 and a usable JWT | I42: Postman environment holds base_url; test users seeded (one active, one disposable for lockout) | J42: 1. POST valid credentials 2. Assert status, schema (token, expiry, user id), response time 3. Decode the JWT and check claims 4. Call a protected endpoint with the token twice | K42: validUser | L42: 200 OK; token present with correct claims and expiry; the token is accepted on repeated authenticated calls | M42: postman/collections/Auth | N42: Planned | O42: Not Run
A43: T-API-AUTH-002 | B43: Postman (API) | C43: Authentication APIs | D43: FR-001 | E43: FR-001-AC2; FR-001-AC7 | F43: P0 | G43: Negative / Boundary | H43: Account locks after 5 consecutive failed logins | I43: Postman environment holds base_url; test users seeded (one active, one disposable for lockout) | J43: 1. POST 4 wrong passwords for a disposable user (expect 401 with a generic error) 2. POST the 5th wrong password 3. POST the correct password | K43: lockoutUser (disposable) | L43: Failures 1-5 return 401 with a generic error; the correct password after the 5th failure is refused with a locked status (e.g. 423/403) and a lockout message; a different user is unaffected | M43: postman/collections/Auth | N43: Planned | O43: Not Run
A44: T-API-AUTH-003 | B44: Postman (API) | C44: Authentication APIs | D44: FR-001 | E44: FR-001-AC5 | F44: P0 | G44: Positive | H44: Logout invalidates the session token | I44: Postman environment holds base_url; test users seeded (one active, one disposable for lockout) | J44: 1. Log in and capture the token 2. Call a protected endpoint (200) 3. Call POST /auth/logout 4. Re-use the same token | L44: Logout returns 200/204; the same token is then rejected with 401 | M44: postman/collections/Auth | N44: Planned | O44: Not Run
A45: T-API-AUTH-004 | B45: Postman (API) | C45: Authentication APIs | D45: FR-001 | E45: FR-001-AC6 | F45: P0 | G45: Positive / Negative | H45: Password reset link issues a single-use token and updates the password | I45: Postman environment holds base_url; test users seeded (one active, one disposable for lockout) | J45: 1. POST forgot-password for a known email 2. Retrieve the reset token from the test mailbox 3. POST reset-password with a new password 4. Log in with the new password 5. Re-use the reset token | K45: Test mailbox or mail-trap access | L45: A reset email/token is issued; the password is changed; the new password works and the old one fails; re-using the token is rejected; unknown emails get a generic response | M45: postman/collections/Auth | N45: Planned | O45: Not Run
A46: T-API-ORD-001 | B46: Postman (API) | C46: Order APIs | D46: FR-002 | E46: FR-002-AC1 | F46: P0 | G46: Positive | H46: POST /orders creates an order with valid items | I46: Valid auth token in environment; SKUs, coupons and addresses seeded | J46: 1. POST an order with valid SKUs and quantities 2. Assert status, schema and values | L46: 201 Created; order id returned; line items, quantities and unit prices match the request/catalogue | M46: postman/collections/Orders | N46: Planned | O46: Not Run
A47: T-API-ORD-002 | B47: Postman (API) | C47: Order APIs | D47: FR-002 | E47: FR-002-AC1 | F47: P0 | G47: Negative / Boundary | H47: POST /orders rejects invalid quantities | I47: Valid auth token in environment; SKUs, coupons and addresses seeded | J47: 1. POST quantity 0 2. POST quantity -1 3. POST a string quantity 4. POST quantity above available stock 5. POST quantity equal to stock | L47: Invalid quantities return 400/422 with field-level messages and no order is created; quantity equal to stock is accepted | M47: postman/collections/Orders | N47: Planned | O47: Not Run
A48: T-API-ORD-003 | B48: Postman (API) | C48: Order APIs | D48: FR-002 | E48: FR-002-AC2 | F48: P0 | G48: Positive | H48: Order total equals items x price + tax | I48: Valid auth token in environment; SKUs, coupons and addresses seeded | J48: 1. Create an order with multiple items 2. Compute the expected total in a Postman test script 3. Compare with the response | L48: subtotal, tax and total in the response equal the expected values to 2 decimals | M48: postman/collections/Orders | N48: Planned | O48: Not Run
...

Sheet E2E Steps
A1: Scenario ID | B1: Scenario | C1: Step | D1: Layer | E1: Action | F1: Expected Result | G1: AC Ref(s) | H1: Step Result | I1: Notes / Evidence
A2: T-E2E-ORD-001 | B2: Complete order lifecycle (login to delivery) | C2: 1 | D2: UI | E2: Log in with a valid customer account | F2: Dashboard is displayed | G2: FR-001-AC1 | H2: Not Run
A3: T-E2E-ORD-001 | B3: Complete order lifecycle (login to delivery) | C3: 2 | D3: UI | E3: Add two products with valid quantities and apply a valid coupon | F3: Cart shows items, discount and total | G3: FR-002-AC1; FR-002-AC3 | H3: Not Run
A4: T-E2E-ORD-001 | B4: Complete order lifecycle (login to delivery) | C4: 3 | D4: UI | E4: Capture the displayed subtotal, discount, tax and total | F4: Values stored for comparison | G4: FR-002-AC2 | H4: Not Run
A5: T-E2E-ORD-001 | B5: Complete order lifecycle (login to delivery) | C5: 4 | D5: API | E5: GET the order/cart via API and compare with the captured UI values | F5: UI values equal API values | G5: FR-007-AC1 | H5: Not Run
A6: T-E2E-ORD-001 | B6: Complete order lifecycle (login to delivery) | C6: 5 | D6: UI | E6: Pay with a valid sandbox card | F6: Payment confirmation is displayed | G6: FR-003-AC2 | H6: Not Run
A7: T-E2E-ORD-001 | B7: Complete order lifecycle (login to delivery) | C7: 6 | D7: API | E7: GET the payment by order id | F7: Status Settled/Authorized; amount equals order total | G7: FR-003-AC2; FR-007-AC1 | H7: Not Run
A8: T-E2E-ORD-001 | B8: Complete order lifecycle (login to delivery) | C8: 7 | D8: SQL | E8: Query Orders and Payments for the order | F8: Order = Paid; exactly one successful payment; Orders.total = Payments.amount = UI total | G8: FR-007-AC2; FR-007-AC4 | H8: Not Run
A9: T-E2E-ORD-001 | B9: Complete order lifecycle (login to delivery) | C9: 8 | D9: API | E9: GET the shipment for the order | F9: Shipment created after payment; tracking number assigned | G9: FR-004-AC1; FR-004-AC2 | H9: Not Run
A10: T-E2E-ORD-001 | B10: Complete order lifecycle (login to delivery) | C10: 9 | D10: SQL | E10: Query Shipments and Inventory | F10: Shipment row exists with a unique tracking number; stock reduced by the ordered quantities | G10: FR-004-AC1; FR-007-AC2 | H10: Not Run
A11: T-E2E-ORD-001 | B11: Complete order lifecycle (login to delivery) | C11: 10 | D11: API | E11: Update the shipment to Shipped, then Delivered with proof of delivery | F11: Statuses update in order; POD stored | G11: FR-004-AC3; FR-004-AC5 | H11: Not Run
A12: T-E2E-ORD-001 | B12: Complete order lifecycle (login to delivery) | C12: 11 | D12: SQL | E12: Query NotificationLog and ProofOfDelivery | F12: SMS/email logged for Shipped and Delivered; POD record exists | G12: FR-004-AC4; FR-004-AC5 | H12: Not Run
A13: T-E2E-ORD-001 | B13: Complete order lifecycle (login to delivery) | C13: 12 | D13: UI | E13: Open the order details page | F13: Status Delivered, tracking number and POD displayed and equal to API values | G13: FR-004-AC3; FR-007-AC1 | H13: Not Run
... A60: T-E2E-INV-001 | B60: Inventory consistency end to end | C60: 12 | D60: SQL | E60: Run the reconciliation query (opening + SUM(ledger) = current) and check for negative stock | F60: No differences; no negative stock; UI = API = DB | G60: FR-007-AC3; FR-007-AC4 | H60: Not Run

Sheet RTM
A1: Requirements Traceability Matrix (Requirement > Test > Defect)
A2: Mapped test IDs are fixed text; counts, coverage and results are formulas reading 'Test Cases'. Yellow columns are for you to fill in.
A4: FR ID | B4: Functional Requirement | C4: AC ID | D4: Acceptance Criterion | E4: Cypress (UI) Tests | F4: Postman (API) Tests | G4: SQL (DB) Tests | H4: E2E Scenarios | I4: # UI | J4: # API | K4: # SQL | L4: # E2E | M4: Total Tests | N4: Coverage | O4: Passed | P4: Failed | Q4: Result | R4: Defect IDs | S4: JIRA Story / Epic | T4: Required Evidence (from brief)
A5: FR-001 | B5: User Authentication & Session Management | C5: FR-001-AC1 | D5: Valid email + password login succeeds | E5: UI-AUTH-001, UI-XBR-001, UI-XBR-002, UI-XBR-003 | F5: API-AUTH-001 | H5: E2E-ORD-001, E2E-PAY-001, E2E-ADR-001, E2E-RE001 | I5: =COUNTIFS('Test Cases'!$E$2:$E$106,"*"&$C5&"*",'Test Cases'!$B$2:$B$106,"Cypress (UI)") -> 4 | J5: =COUNTIFS('Test Cases'!$E$2:$E$106,"*"&$C5&"*",'Test Cases'!$B$2:$B$106,"Postman (API)") -> 1 | K5: =COUNTIFS('Test Cases'!$E$2:$E$106,"*"&$C5&"*",'Test Cases'!$B$2:$B$106,"SQL (DB)") -> 0 | L5: =COUNTIFS('Test Cases'!$E$2:$E$106,"*"&$C5&"*",'Test Cases'!$B$2:$B$106,"E2E") -> 4 | M5: =SUM(I5:L5) -> 9 | N5: =IF(M5=0,"NOT COVERED","Covered") -> Covered | O5: =COUNTIFS('Test Cases'!$E$2:$E$106,"*"&$C5&"*",'Test Cases'!$O$2:$O$106,"Pass") -> 0 | P5: =COUNTIFS('Test Cases'!$E$2:$E$106,"*"&$C5&"*",'Test Cases'!$O$2:$O$106,"Fail") -> 0 | Q5: =IF(M5=0,"-",IF(P5>0,"FAIL",IF(O5=M5,"PASS",IF(O5=0,"NOT RUN","IN PROGRESS")))) -> NOT RUN | T5: Cypress test results + JWT/Session token validation
A6: FR-001 | B6: User Authentication & Session Management | C6: FR-001-AC2 | D6: Invalid credentials rejected with clear error | E6: UI-AUTH-002 | F6: API-AUTH-002, API-ERR-001 | I6: =COUNTIFS('Test Cases'!$E$2:$E$106,"*"&$C6&"*",'Test Cases'!$B$2:$B$106,"Cypress (UI)") -> 1 | J6: =COUNTIFS('Test Cases'!$E$2:$E$106,"*"&$C6&"*",'Test Cases'!$B$2:$B$106,"Postman (API)") -> 2 | K6: =COUNTIFS('Test Cases'!$E$2:$E$106,"*"&$C6&"*",'Test Cases'!$B$2:$B$106,"SQL (DB)") -> 0 | L6: =COUNTIFS('Test Cases'!$E$2:$E$106,"*"&$C6&"*",'Test Cases'!$B$2:$B$106,"E2E") -> 0 | M6: =SUM(I6:L6) -> 3 | N6: =IF(M6=0,"NOT COVERED","Covered") -> Covered | O6: =COUNTIFS('Test Cases'!$E$2:$E$106,"*"&$C6&"*",'Test Cases'!$O$2:$O$106,"Pass") -> 0 | P6: =COUNTIFS('Test Cases'!$E$2:$E$106,"*"&$C6&"*",'Test Cases'!$O$2:$O$106,"Fail") -> 0 | Q6: =IF(M6=0,"-",IF(P6>0,"FAIL",IF(O6=M6,"PASS",IF(O6=0,"NOT RUN","IN PROGRESS")))) -> NOT RUN | T6: Cypress test results + JWT/Session token validation
A7: FR-001 | B7: User Authentication & Session Management | C7: FR-001-AC3 | D7: Session persists across page navigation | E7: UI-AUTH-003, UI-XBR-001, UI-XBR-002, UI-XBR-003 | F7: API-AUTH-001 | I7: =COUNTIFS('Test Cases'!$E$2:$E$106,"*"&$C7&"*",'Test Cases'!$B$2:$B$106,"Cypress (UI)") -> 4 | J7: =COUNTIFS('Test Cases'!$E$2:$E$106,"*"&$C7&"*",'Test Cases'!$B$2:$B$106,"Postman (API)") -> 1 | K7: =COUNTIFS('Test Cases'!$E$2:$E$106,"*"&$C7&"*",'Test Cases'!$B$2:$B$106,"SQL (DB)") -> 0 | L7: =COUNTIFS('Test Cases'!$E$2:$E$106,"*"&$C7&"*",'Test Cases'!$B$2:$B$106,"E2E") -> 0 | M7: =SUM(I7:L7) -> 5 | N7: =IF(M7=0,"NOT COVERED","Covered") -> Covered | O7: =COUNTIFS('Test Cases'!$E$2:$E$106,"*"&$C7&"*",'Test Cases'!$O$2:$O$106,"Pass") -> 0 | P7: =COUNTIFS('Test Cases'!$E$2:$E$106,"*"&$C7&"*",'Test Cases'!$O$2:$O$106,"Fail") -> 0 | Q7: =IF(M7=0,"-",IF(P7>0,"FAIL",IF(O7=M7,"PASS",IF(O7=0,"NOT RUN","IN PROGRESS")))) -> NOT RUN | T7: Cypress test results + JWT/Session token validation
A8: FR-001 | B8: User Authentication & Session Management | C8: FR-001-AC4 | D8: Session expires after 30 minutes of inactivity | E8: UI-AUTH-004 | I8: =COUNTIFS('Test Cases'!$E$2:$E$106,"*"&$C8&"*",'Test Cases'!$B$2:$B$106,"Cypress (UI)") -> 1 | J8: =COUNTIFS('Test Cases'!$E$2:$E$106,"*"&$C8&"*",'Test Cases'!$B$2:$B$106,"Postman (API)") -> 0 | K8: =COUNTIFS('Test Cases'!$E$2:$E$106,"*"&$C8&"*",'Test Cases'!$B$2:$B$106,"SQL (DB)") -> 0 | L8: =COUNTIFS('Test Cases'!$E$2:$E$106,"*"&$C8&"*",'Test Cases'!$B$2:$B$106,"E2E") -> 0 | M8: =SUM(I8:L8) -> 1 | N8: =IF(M8=0,"NOT COVERED","Covered") -> Covered | O8: =COUNTIFS('Test Cases'!$E$2:$E$106,"*"&$C8&"*",'Test Cases'!$O$2:$O$106,"Pass") -> 0 | P8: =COUNTIFS('Test Cases'!$E$2:$E$106,"*"&$C8&"*",'Test Cases'!$O$2:$O$106,"Fail") -> 0 | Q8: =IF(M8=0,"-",IF(P8>0,"FAIL",IF(O8=M8,"PASS",IF(O8=0,"NOT RUN","IN PROGRESS")))) -> NOT RUN | T8: Cypress test results + JWT/Session token validation
A9: FR-001 | B9: User Authentication & Session Management | C9: FR-001-AC5 | D9: User can logout, invalidating session | F9: API-AUTH-003 | I9: =COUNTIFS('Test Cases'!$E$2:$E$106,"*"&$C9&"*",'Test Cases'!$B$2:$B$106,"Cypress (UI)") -> 0 | J9: =COUNTIFS('Test Cases'!$E$2:$E$106,"*"&$C9&"*",'Test Cases'!$B$2:$B$106,"Postman (API)") -> 1 | K9: =COUNTIFS('Test Cases'!$E$2:$E$106,"*"&$C9&"*",'Test Cases'!$B$2:$B$106,"SQL (DB)") -> 0 | L9: =COUNTIFS('Test Cases'!$E$2:$E$106,"*"&$C9&"*",'Test Cases'!$B$2:$B$106,"E2E") -> 0 | M9: =SUM(I9:L9) -> 1 | N9: =IF(M9=0,"NOT COVERED","Covered") -> Covered | O9: =COUNTIFS('Test Cases'!$E$2:$E$106,"*"&$C9&"*",'Test Cases'!$O$2:$O$106,"Pass") -> 0 | P9: =COUNTIFS('Test Cases'!$E$2:$E$106,"*"&$C9&"*",'Test Cases'!$O$2:$O$106,"Fail") -> 0 | Q9: =IF(M9=0,"-",IF(P9>0,"FAIL",IF(O9=M9,"PASS",IF(O9=0,"NOT RUN","IN PROGRESS")))) -> NOT RUN | T9: Cypress test results + JWT/Session token validation
A10: FR-001 | B10: User Authentication & Session Management | C10: FR-001-AC6 | D10: Password reset via email link works | F10: API-AUTH-004 | I10: =COUNTIFS('Test Cases'!$E$2:$E$106,"*"&$C10&"*",'Test Cases'!$B$2:$B$106,"Cypress (UI)") -> 0 | J10: =COUNTIFS('Test Cases'!$E$2:$E$106,"*"&$C10&"*",'Test Cases'!$B$2:$B$106,"Postman (API)") -> 1 | K10: =COUNTIFS('Test Cases'!$E$2:$E$106,"*"&$C10&"*",'Test Cases'!$B$2:$B$106,"SQL (DB)") -> 0 | L10: =COUNTIFS('Test Cases'!$E$2:$E$106,"*"&$C10&"*",'Test Cases'!$B$2:$B$106,"E2E") -> 0 | M10: =SUM(I10:L10) -> 1 | N10: =IF(M10=0,"NOT COVERED","Covered") -> Covered | O10: =COUNTIFS('Test Cases'!$E$2:$E$106,"*"&$C10&"*",'Test Cases'!$O$2:$O$106,"Pass") -> 0 | P10: =COUNTIFS('Test Cases'!$E$2:$E$106,"*"&$C10&"*",'Test Cases'!$O$2:$O$106,"Fail") -> 0 | Q10: =IF(M10=0,"-",IF(P10>0,"FAIL",IF(O10=M10,"PASS",IF(O10=0,"NOT RUN","IN PROGRESS")))) -> NOT RUN | T10: Cypress test results + JWT/Session token validation
A11: FR-001 | B11: User Authentication & Session Management | C11: FR-001-AC7 | D11: Account lockout after 5 failed attempts | F11: API-AUTH-002 | I11: =COUNTIFS('Test Cases'!$E$2:$E$106,"*"&$C11&"*",'Test Cases'!$B$2:$B$106,"Cypress (UI)") -> 0 | J11: =COUNTIFS('Test Cases'!$E$2:$E$106,"*"&$C11&"*",'Test Cases'!$B$2:$B$106,"Postman (API)") -> 1 | K11: =COUNTIFS('Test Cases'!$E$2:$E$106,"*"&$C11&"*",'Test Cases'!$B$2:$B$106,"SQL (DB)") -> 0 | L11: =COUNTIFS('Test Cases'!$E$2:$E$106,"*"&$C11&"*",'Test Cases'!$B$2:$B$106,"E2E") -> 0 | M11: =SUM(I11:L11) -> 1 | N11: =IF(M11=0,"NOT COVERED","Covered") -> Covered | O11: =COUNTIFS('Test Cases'!$E$2:$E$106,"*"&$C11&"*",'Test Cases'!$O$2:$O$106,"Pass") -> 0 | P11: =COUNTIFS('Test Cases'!$E$2:$E$106,"*"&$C11&"*",'Test Cases'!$O$2:$O$106,"Fail") -> 0 | Q11: =IF(M11=0,"-",IF(P11>0,"FAIL",IF(O11=M11,"PASS",IF(O11=0,"NOT RUN","IN PROGRESS")))) -> NOT RUN | T11: Cypress test results + JWT/Session token validation
A12: FR-002 | B12: Order Management | C12: FR-002-AC1 | D12: Add products to order with quantity validation | E12: UI-ORD-001, UI-ORD-002 | F12: API-ORD-001, API-ORD-002, API-ERR-002 | G12: DB-INV-001 | H12: E2E-ORD-001, E2E-PAY-001, E2E-ADR-001, E2E-INV-001 | I12: =COUNTIFS('Test Cases'!$E$2:$E$106,"*"&$C12&"*",'Test Cases'!$B$2:$B$106,"Cypress (UI)") -> 2 | J12: =COUNTIFS('Test Cases'!$E$2:$E$106,"*"&$C12&"*",'Test Cases'!$B$2:$B$106,"Postman (API)") -> 3 | K12: =COUNTIFS('Test Cases'!$E$2:$E$106,"*"&$C12&"*",'Test Cases'!$B$2:$B$106,"SQL (DB)") -> 1 | L12: =COUNTIFS('Test Cases'!$E$2:$E$106,"*"&$C12&"*",'Test Cases'!$B$2:$B$106,"E2E") -> 4 | M12: =SUM(I12:L12) -> 10 | N12: =IF(M12=0,"NOT COVERED","Covered") -> Covered | O12: =COUNTIFS('Test Cases'!$E$2:$E$106,"*"&$C12&"*",'Test Cases'!$O$2:$O$106,"Pass") -> 0 | P12: =COUNTIFS('Test Cases'!$E$2:$E$106,"*"&$C12&"*",'Test Cases'!$O$2:$O$106,"Fail") -> 0 | Q12: =IF(M12=0,"-",IF(P12>0,"FAIL",IF(O12=M12,"PASS",IF(O12=0,"NOT RUN","IN PROGRESS")))) -> NOT RUN | T12: UI automation logs + SQL Order Integrity queries
A13: FR-002 | B13: Order Management | C13: FR-002-AC2 | D13: Calculate order total (items x price + tax) | E13: UI-ORD-003, UI-XBR-004, UI-XBR-005 | F13: API-ORD-003 | G13: DB-ORD-002 | H13: E2E-ORD-001 | I13: =COUNTIFS('Test Cases'!$E$2:$E$106,"*"&$C13&"*",'Test Cases'!$B$2:$B$106,"Cypress (UI)") -> 3 | J13: =COUNTIFS('Test Cases'!$E$2:$E$106,"*"&$C13&"*",'Test Cases'!$B$2:$B$106,"Postman (API)") -> 1 | K13: =COUNTIFS('Test Cases'!$E$2:$E$106,"*"&$C13&"*",'Test Cases'!$B$2:$B$106,"SQL (DB)") -> 1 | L13: =COUNTIFS('Test Cases'!$E$2:$E$106,"*"&$C13&"*",'Test Cases'!$B$2:$B$106,"E2E") -> 1 | M13: =SUM(I13:L13) -> 6 | N13: =IF(M13=0,"NOT COVERED","Covered") -> Covered | O13: =COUNTIFS('Test Cases'!$E$2:$E$106,"*"&$C13&"*",'Test Cases'!$O$2:$O$106,"Pass") -> 0 | P13: =COUNTIFS('Test Cases'!$E$2:$E$106,"*"&$C13&"*",'Test Cases'!$O$2:$O$106,"Fail") -> 0 | Q13: =IF(M13=0,"-",IF(P13>0,"FAIL",IF(O13=M13,"PASS",IF(O13=0,"NOT RUN","IN PROGRESS")))) -> NOT RUN | T13: UI automation logs + SQL Order Integrity queries
A14: FR-002 | B14: Order Management | C14: FR-002-AC3 | D14: Apply valid coupon codes for discounts | E14: UI-ORD-004, UI-ORD-005 | F14: API-ORD-004, API-ORD-005 | H14: E2E-ORD-001 | I14: =COUNTIFS('Test Cases'!$E$2:$E$106,"*"&$C14&"*",'Test Cases'!$B$2:$B$106,"Cypress (UI)") -> 2 | J14: =COUNTIFS('Test Cases'!$E$2:$E$106,"*"&$C14&"*",'Test Cases'!$B$2:$B$106,"Postman (API)") -> 2 | K14: =COUNTIFS('Test Cases'!$E$2:$E$106,"*"&$C14&"*",'Test Cases'!$B$2:$B$106,"SQL (DB)") -> 0 | L14: =COUNTIFS('Test Cases'!$E$2:$E$106,"*"&$C14&"*",'Test Cases'!$B$2:$B$106,"E2E") -> 1 | M14: =SUM(I14:L14) -> 5 | N14: =IF(M14=0,"NOT COVERED","Covered") -> Covered | O14: =COUNTIFS('Test Cases'!$E$2:$E$106,"*"&$C14&"*",'Test Cases'!$O$2:$O$106,"Pass") -> 0 | P14: =COUNTIFS('Test Cases'!$E$2:$E$106,"*"&$C14&"*",'Test Cases'!$O$2:$O$106,"Fail") -> 0 | Q14: =IF(M14=0,"-",IF(P14>0,"FAIL",IF(O14=M14,"PASS",IF(O14=0,"NOT RUN","IN PROGRESS")))) -> NOT RUN | T14: UI automation logs + SQL Order Integrity queries
A15: FR-002 | B15: Order Management | C15: FR-002-AC4 | D15: Modify order pre-payment (change quantity, address) | E15: UI-ORD-006, UI-ORD-007 | F15: API-ORD-006 | H15: E2E-ADR-001 | I15: =COUNTIFS('Test Cases'!$E$2:$E$106,"*"&$C15&"*",'Test Cases'!$B$2:$B$106,"Cypress (UI)") -> 2 | J15: =COUNTIFS('Test Cases'!$E$2:$E$106,"*"&$C15&"*",'Test Cases'!$B$2:$B$106,"Postman (API)") -> 1 | K15: =COUNTIFS('Test Cases'!$E$2:$E$106,"*"&$C15&"*",'Test Cases'!$B$2:$B$106,"SQL (DB)") -> 0 | L15: =COUNTIFS('Test Cases'!$E$2:$E$106,"*"&$C15&"*",'Test Cases'!$B$2:$B$106,"E2E") -> 1 | M15: =SUM(I15:L15) -> 4 | N15: =IF(M15=0,"NOT COVERED","Covered") -> Covered | O15: =COUNTIFS('Test Cases'!$E$2:$E$106,"*"&$C15&"*",'Test Cases'!$O$2:$O$106,"Pass") -> 0 | P15: =COUNTIFS('Test Cases'!$E$2:$E$106,"*"&$C15&"*",'Test Cases'!$O$2:$O$106,"Fail") -> 0 | Q15: =IF(M15=0,"-",IF(P15>0,"FAIL",IF(O15=M15,"PASS",IF(O15=0,"NOT RUN","IN PROGRESS")))) -> NOT RUN | T15: UI automation logs + SQL Order Integrity queries
A16: FR-002 | B16: Order Management | C16: FR-002-AC5 | D16: Cannot modify order post-payment | E16: UI-ORD-008 | F16: API-ORD-007 | G16: DB-ORD-004 | H16: E2E-ADR-001 | I16: =COUNTIFS('Test Cases'!$E$2:$E$106,"*"&$C16&"*",'Test Cases'!$B$2:$B$106,"Cypress (UI)") -> 1 | J16: =COUNTIFS('Test Cases'!$E$2:$E$106,"*"&$C16&"*",'Test Cases'!$B$2:$B$106,"Postman (API)") -> 1 | K16: =COUNTIFS('Test Cases'!$E$2:$E$106,"*"&$C16&"*",'Test Cases'!$B$2:$B$106,"SQL (DB)") -> 1 | L16: =COUNTIFS('Test Cases'!$E$2:$E$106,"*"&$C16&"*",'Test Cases'!$B$2:$B$106,"E2E") -> 1 | M16: =SUM(I16:L16) -> 4 | N16: =IF(M16=0,"NOT COVERED","Covered") -> Covered | O16: =COUNTIFS('Test Cases'!$E$2:$E$106,"*"&$C16&"*",'Test Cases'!$O$2:$O$106,"Pass") -> 0 | P16: =COUNTIFS('Test Cases'!$E$2:$E$106,"*"&$C16&"*",'Test Cases'!$O$2:$O$106,"Fail") -> 0 | Q16: =IF(M16=0,"-",IF(P16>0,"FAIL",IF(O16=M16,"PASS",IF(O16=0,"NOT RUN","IN PROGRESS")))) -> NOT RUN | T16: UI automation logs + SQL Order Integrity queries
A17: FR-002 | B17: Order Management | C17: FR-002-AC6 | D17: Cancel order returns inventory | E17: UI-ORD-009 | F17: API-ORD-008 | G17: DB-ORD-004, DB-INV-003 | H17: E2E-INV-001 | I17: =COUNTIFS('Test Cases'!$E$2:$E$106,"*"&$C17&"*",'Test Cases'!$B$2:$B$106,"Cypress (UI)") -> 1 | J17: =COUNTIFS('Test Cases'!$E$2:$E$106,"*"&$C17&"*",'Test Cases'!$B$2:$B$106,"Postman (API)") -> 1 | K17: =COUNTIFS('Test Cases'!$E$2:$E$106,"*"&$C17&"*",'Test Cases'!$B$2:$B$106,"SQL (DB)") -> 2 | L17: =COUNTIFS('Test Cases'!$E$2:$E$106,"*"&$C17&"*",'Test Cases'!$B$2:$B$106,"E2E") -> 1 | M17: =SUM(I17:L17) -> 5 | N17: =IF(M17=0,"NOT COVERED","Covered") -> Covered | O17: =COUNTIFS('Test Cases'!$E$2:$E$106,"*"&$C17&"*",'Test Cases'!$O$2:$O$106,"Pass") -> 0 | P17: =COUNTIFS('Test Cases'!$E$2:$E$106,"*"&$C17&"*",'Test Cases'!$O$2:$O$106,"Fail") -> 0 | Q17: =IF(M17=0,"-",IF(P17>0,"FAIL",IF(O17=M17,"PASS",IF(O17=0,"NOT RUN","IN PROGRESS")))) -> NOT RUN | T17: UI automation logs + SQL Order Integrity queries
A18: FR-002 | B18: Order Management | C18: FR-002-AC7 | D18: Idempotency (no duplicate orders) | E18: UI-ORD-010 | F18: API-ORD-009, API-ERR-003 | G18: DB-ORD-003 | I18: =COUNTIFS('Test Cases'!$E$2:$E$106,"*"&$C18&"*",'Test Cases'!$B$2:$B$106,"Cypress (UI)") -> 1 | J18: =COUNTIFS('Test Cases'!$E$2:$E$106,"*"&$C18&"*",'Test Cases'!$B$2:$B$106,"Postman (API)") -> 2 | K18: =COUNTIFS('Test Cases'!$E$2:$E$106,"*"&$C18&"*",'Test Cases'!$B$2:$B$106,"SQL (DB)") -> 1 | L18: =COUNTIFS('Test Cases'!$E$2:$E$106,"*"&$C18&"*",'Test Cases'!$B$2:$B$106,"E2E") -> 0 | M18: =SUM(I18:L18) -> 4 | N18: =IF(M18=0,"NOT COVERED","Covered") -> Covered | O18: =COUNTIFS('Test Cases'!$E$2:$E$106,"*"&$C18&"*",'Test Cases'!$O$2:$O$106,"Pass") -> 0 | P18: =COUNTIFS('Test Cases'!$E$2:$E$106,"*"&$C18&"*",'Test Cases'!$O$2:$O$106,"Fail") -> 0 | Q18: =IF(M18=0,"-",IF(P18>0,"FAIL",IF(O18=M18,"PASS",IF(O18=0,"NOT RUN","IN PROGRESS")))) -> NOT RUN | T18: UI automation logs + SQL Order Integrity queries
A19: FR-003 | B19: Payment Processing | C19: FR-003-AC1 | D19: Credit card validation (format, expiry, CVV) | E19: UI-PAY-002, UI-PAY-003, UI-PAY-004 | F19: API-PAY-002, API-PAY-003, API-PAY-004 | H19: E2E-PAY-001 | I19: =COUNTIFS('Test Cases'!$E$2:$E$106,"*"&$C19&"*",'Test Cases'!$B$2:$B$106,"Cypress (UI)") -> 3 | J19: =COUNTIFS('Test Cases'!$E$2:$E$106,"*"&$C19&"*",'Test Cases'!$B$2:$B$106,"Postman (API)") -> 3 | K19: =COUNTIFS('Test Cases'!$E$2:$E$106,"*"&$C19&"*",'Test Cases'!$B$2:$B$106,"SQL (DB)") -> 0 | L19: =COUNTIFS('Test Cases'!$E$2:$E$106,"*"&$C19&"*",'Test Cases'!$B$2:$B$106,"E2E") -> 1 | M19: =SUM(I19:L19) -> 7 | N19: =IF(M19=0,"NOT COVERED","Covered") -> Covered | O19: =COUNTIFS('Test Cases'!$E$2:$E$106,"*"&$C19&"*",'Test Cases'!$O$2:$O$106,"Pass") -> 0 | P19: =COUNTIFS('Test Cases'!$E$2:$E$106,"*"&$C19&"*",'Test Cases'!$O$2:$O$106,"Fail") -> 0 | Q19: =IF(M19=0,"-",IF(P19>0,"FAIL",IF(O19=M19,"PASS",IF(O19=0,"NOT RUN","IN PROGRESS")))) -> NOT RUN | T19: Transaction status records + Payment ledger SQL verification
A20: FR-003 | B20: Payment Processing | C20: FR-003-AC2 | D20: Payment authorization succeeds for valid cards | E20: UI-PAY-001 | F20: API-PAY-001 | G20: DB-PAY-002 | H20: E2E-ORD-001, E2E-PAY-001, E2E-ADR-001, E2E-INV-001 | I20: =COUNTIFS('Test Cases'!$E$2:$E$106,"*"&$C20&"*",'Test Cases'!$B$2:$B$106,"Cypress (UI)") -> 1 | J20: =COUNTIFS('Test Cases'!$E$2:$E$106,"*"&$C20&"*",'Test Cases'!$B$2:$B$106,"Postman (API)") -> 1 | K20: =COUNTIFS('Test Cases'!$E$2:$E$106,"*"&$C20&"*",'Test Cases'!$B$2:$B$106,"SQL (DB)") -> 1 | L20: =COUNTIFS('Test Cases'!$E$2:$E$106,"*"&$C20&"*",'Test Cases'!$B$2:$B$106,"E2E") -> 4 | M20: =SUM(I20:L20) -> 7 | N20: =IF(M20=0,"NOT COVERED","Covered") -> Covered | O20: =COUNTIFS('Test Cases'!$E$2:$E$106,"*"&$C20&"*",'Test Cases'!$O$2:$O$106,"Pass") -> 0 | P20: =COUNTIFS('Test Cases'!$E$2:$E$106,"*"&$C20&"*",'Test Cases'!$O$2:$O$106,"Fail") -> 0 | Q20: =IF(M20=0,"-",IF(P20>0,"FAIL",IF(O20=M20,"PASS",IF(O20=0,"NOT RUN","IN PROGRESS")))) -> NOT RUN | T20: Transaction status records + Payment ledger SQL verification
A21: FR-003 | B21: Payment Processing | C21: FR-003-AC3 | D21: Payment declined gracefully for invalid cards | E21: UI-PAY-005 | F21: API-PAY-005 | G21: DB-PAY-003 | H21: E2E-PAY-001 | I21: =COUNTIFS('Test Cases'!$E$2:$E$106,"*"&$C21&"*",'Test Cases'!$B$2:$B$106,"Cypress (UI)") -> 1 | J21: =COUNTIFS('Test Cases'!$E$2:$E$106,"*"&$C21&"*",'Test Cases'!$B$2:$B$106,"Postman (API)") -> 1 | K21: =COUNTIFS('Test Cases'!$E$2:$E$106,"*"&$C21&"*",'Test Cases'!$B$2:$B$106,"SQL (DB)") -> 1 | L21: =COUNTIFS('Test Cases'!$E$2:$E$106,"*"&$C21&"*",'Test Cases'!$B$2:$B$106,"E2E") -> 1 | M21: =SUM(I21:L21) -> 4 | N21: =IF(M21=0,"NOT COVERED","Covered") -> Covered | O21: =COUNTIFS('Test Cases'!$E$2:$E$106,"*"&$C21&"*",'Test Cases'!$O$2:$O$106,"Pass") -> 0 | P21: =COUNTIFS('Test Cases'!$E$2:$E$106,"*"&$C21&"*",'Test Cases'!$O$2:$O$106,"Fail") -> 0 | Q21: =IF(M21=0,"-",IF(P21>0,"FAIL",IF(O21=M21,"PASS",IF(O21=0,"NOT RUN","IN PROGRESS")))) -> NOT RUN | T21: Transaction status records + Payment ledger SQL verification
A22: FR-003 | B22: Payment Processing | C22: FR-003-AC4 | D22: No double-charging (duplicate prevention) | E22: UI-PAY-006 | F22: API-PAY-006 | G22: DB-PAY-001 | H22: E2E-PAY-001 | I22: =COUNTIFS('Test Cases'!$E$2:$E$106,"*"&$C22&"*",'Test Cases'!$B$2:$B$106,"Cypress (UI)") -> 1 | J22: =COUNTIFS('Test Cases'!$E$2:$E$106,"*"&$C22&"*",'Test Cases'!$B$2:$B$106,"Postman (API)") -> 1 | K22: =COUNTIFS('Test Cases'!$E$2:$E$106,"*"&$C22&"*",'Test Cases'!$B$2:$B$106,"SQL (DB)") -> 1 | L22: =COUNTIFS('Test Cases'!$E$2:$E$106,"*"&$C22&"*",'Test Cases'!$B$2:$B$106,"E2E") -> 1 | M22: =SUM(I22:L22) -> 4 | N22: =IF(M22=0,"NOT COVERED","Covered") -> Covered | O22: =COUNTIFS('Test Cases'!$E$2:$E$106,"*"&$C22&"*",'Test Cases'!$O$2:$O$106,"Pass") -> 0 | P22: =COUNTIFS('Test Cases'!$E$2:$E$106,"*"&$C22&"*",'Test Cases'!$O$2:$O$106,"Fail") -> 0 | Q22: =IF(M22=0,"-",IF(P22>0,"FAIL",IF(O22=M22,"PASS",IF(O22=0,"NOT RUN","IN PROGRESS")))) -> NOT RUN | T22: Transaction status records + Payment ledger SQL verification
A23: FR-003 | B23: Payment Processing | C23: FR-003-AC5 | D23: Refund functionality works correctly | F23: API-PAY-007, API-PAY-008 | G23: DB-PAY-004 | H23: E2E-RE001 | I23: =COUNTIFS('Test Cases'!$E$2:$E$106,"*"&$C23&"*",'Test Cases'!$B$2:$B$106,"Cypress (UI)") -> 0 | J23: =COUNTIFS('Test Cases'!$E$2:$E$106,"*"&$C23&"*",'Test Cases'!$B$2:$B$106,"Postman (API)") -> 2 | K23: =COUNTIFS('Test Cases'!$E$2:$E$106,"*"&$C23&"*",'Test Cases'!$B$2:$B$106,"SQL (DB)") -> 1 | L23: =COUNTIFS('Test Cases'!$E$2:$E$106,"*"&$C23&"*",'Test Cases'!$B$2:$B$106,"E2E") -> 1 | M23: =SUM(I23:L23) -> 4 | N23: =IF(M23=0,"NOT COVERED","Covered") -> Covered | O23: =COUNTIFS('Test Cases'!$E$2:$E$106,"*"&$C23&"*",'Test Cases'!$O$2:$O$106,"Pass") -> 0 | P23: =COUNTIFS('Test Cases'!$E$2:$E$106,"*"&$C23&"*",'Test Cases'!$O$2:$O$106,"Fail") -> 0 | Q23: =IF(M23=0,"-",IF(P23>0,"FAIL",IF(O23=M23,"PASS",IF(O23=0,"NOT RUN","IN PROGRESS")))) -> NOT RUN | T23: Transaction status records + Payment ledger SQL verification
A24: FR-004 | B24: Shipment & Delivery Tracking | C24: FR-004-AC1 | D24: Shipment created after payment confirmed | E24: UI-DEL-004 | F24: API-SHP-001, API-SHP-002 | G24: DB-SHP-001 | H24: E2E-ORD-001, E2E-PAY-001, E2E-ADR-001 | I24: =COUNTIFS('Test Cases'!$E$2:$E$106,"*"&$C24&"*",'Test Cases'!$B$2:$B$106,"Cypress (UI)") -> 1 | J24: =COUNTIFS('Test Cases'!$E$2:$E$106,"*"&$C24&"*",'Test Cases'!$B$2:$B$106,"Postman (API)") -> 2 | K24: =COUNTIFS('Test Cases'!$E$2:$E$106,"*"&$C24&"*",'Test Cases'!$B$2:$B$106,"SQL (DB)") -> 1 | L24: =COUNTIFS('Test Cases'!$E$2:$E$106,"*"&$C24&"*",'Test Cases'!$B$2:$B$106,"E2E") -> 3 | M24: =SUM(I24:L24) -> 7 | N24: =IF(M24=0,"NOT COVERED","Covered") -> Covered | O24: =COUNTIFS('Test Cases'!$E$2:$E$106,"*"&$C24&"*",'Test Cases'!$O$2:$O$106,"Pass") -> 0 | P24: =COUNTIFS('Test Cases'!$E$2:$E$106,"*"&$C24&"*",'Test Cases'!$O$2:$O$106,"Fail") -> 0 | Q24: =IF(M24=0,"-",IF(P24>0,"FAIL",IF(O24=M24,"PASS",IF(O24=0,"NOT RUN","IN PROGRESS")))) -> NOT RUN | T24: Tracking status flow logs + SMS/Email notification logs
A25: FR-004 | B25: Shipment & Delivery Tracking | C25: FR-004-AC2 | D25: Tracking number assigned and visible | E25: UI-DEL-001, UI-DEL-005, UI-XBR-006 | F25: API-SHP-003, API-DEL-001 | G25: DB-SHP-002 | H25: E2E-ORD-001, E2E-ADR-001 | I25: =COUNTIFS('Test Cases'!$E$2:$E$106,"*"&$C25&"*",'Test Cases'!$B$2:$B$106,"Cypress (UI)") -> 3 | J25: =COUNTIFS('Test Cases'!$E$2:$E$106,"*"&$C25&"*",'Test Cases'!$B$2:$B$106,"Postman (API)") -> 2 | K25: =COUNTIFS('Test Cases'!$E$2:$E$106,"*"&$C25&"*",'Test Cases'!$B$2:$B$106,"SQL (DB)") -> 1 | L25: =COUNTIFS('Test Cases'!$E$2:$E$106,"*"&$C25&"*",'Test Cases'!$B$2:$B$106,"E2E") -> 2 | M25: =SUM(I25:L25) -> 8 | N25: =IF(M25=0,"NOT COVERED","Covered") -> Covered | O25: =COUNTIFS('Test Cases'!$E$2:$E$106,"*"&$C25&"*",'Test Cases'!$O$2:$O$106,"Pass") -> 0 | P25: =COUNTIFS('Test Cases'!$E$2:$E$106,"*"&$C25&"*",'Test Cases'!$O$2:$O$106,"Fail") -> 0 | Q25: =IF(M25=0,"-",IF(P25>0,"FAIL",IF(O25=M25,"PASS",IF(O25=0,"NOT RUN","IN PROGRESS")))) -> NOT RUN | T25: Tracking status flow logs + SMS/Email notification logs
A26: FR-004 | B26: Shipment & Delivery Tracking | C26: FR-004-AC3 | D26: Status updates correctly (Shipped -> Delivered) | E26: UI-DEL-002, UI-DEL-003, UI-XBR-006 | F26: API-SHP-004, API-SHP-005, API-DEL-001, API-DEL-002 | G26: DB-SHP-003 | H26: E2E-ORD-001, E2E-ADR-001 | I26: =COUNTIFS('Test Cases'!$E$2:$E$106,"*"&$C26&"*",'Test Cases'!$B$2:$B$106,"Cypress (UI)") -> 3 | J26: =COUNTIFS('Test Cases'!$E$2:$E$106,"*"&$C26&"*",'Test Cases'!$B$2:$B$106,"Postman (API)") -> 4 | K26: =COUNTIFS('Test Cases'!$E$2:$E$106,"*"&$C26&"*",'Test Cases'!$B$2:$B$106,"SQL (DB)") -> 1 | L26: =COUNTIFS('Test Cases'!$E$2:$E$106,"*"&$C26&"*",'Test Cases'!$B$2:$B$106,"E2E") -> 2 | M26: =SUM(I26:L26) -> 10 | N26: =IF(M26=0,"NOT COVERED","Covered") -> Covered | O26: =COUNTIFS('Test Cases'!$E$2:$E$106,"*"&$C26&"*",'Test Cases'!$O$2:$O$106,"Pass") -> 0 | P26: =COUNTIFS('Test Cases'!$E$2:$E$106,"*"&$C26&"*",'Test Cases'!$O$2:$O$106,"Fail") -> 0 | Q26: =IF(M26=0,"-",IF(P26>0,"FAIL",IF(O26=M26,"PASS",IF(O26=0,"NOT RUN","IN PROGRESS")))) -> NOT RUN | T26: Tracking status flow logs + SMS/Email notification logs
A27: FR-004 | B27: Shipment & Delivery Tracking | C27: FR-004-AC4 | D27: Customer notifications (SMS/Email) triggered | F27: API-SHP-006, API-DEL-004 | G27: DB-AUD-003 | H27: E2E-ORD-001 | I27: =COUNTIFS('Test Cases'!$E$2:$E$106,"*"&$C27&"*",'Test Cases'!$B$2:$B$106,"Cypress (UI)") -> 0 | J27: =COUNTIFS('Test Cases'!$E$2:$E$106,"*"&$C27&"*",'Test Cases'!$B$2:$B$106,"Postman (API)") -> 2 | K27: =COUNTIFS('Test Cases'!$E$2:$E$106,"*"&$C27&"*",'Test Cases'!$B$2:$B$106,"SQL (DB)") -> 1 | L27: =COUNTIFS('Test Cases'!$E$2:$E$106,"*"&$C27&"*",'Test Cases'!$B$2:$B$106,"E2E") -> 1 | M27: =SUM(I27:L27) -> 4 | N27: =IF(M27=0,"NOT COVERED","Covered") -> Covered | O27: =COUNTIFS('Test Cases'!$E$2:$E$106,"*"&$C27&"*",'Test Cases'!$O$2:$O$106,"Pass") -> 0 | P27: =COUNTIFS('Test Cases'!$E$2:$E$106,"*"&$C27&"*",'Test Cases'!$O$2:$O$106,"Fail") -> 0 | Q27: =IF(M27=0,"-",IF(P27>0,"FAIL",IF(O27=M27,"PASS",IF(O27=0,"NOT RUN","IN PROGRESS")))) -> NOT RUN | T27: Tracking status flow logs + SMS/Email notification logs
A28: FR-004 | B28: Shipment & Delivery Tracking | C28: FR-004-AC5 | D28: Proof of delivery (POD) recorded | E28: UI-DEL-006 | F28: API-DEL-003 | G28: DB-SHP-004 | H28: E2E-ORD-001 | I28: =COUNTIFS('Test Cases'!$E$2:$E$106,"*"&$C28&"*",'Test Cases'!$B$2:$B$106,"Cypress (UI)") -> 1 | J28: =COUNTIFS('Test Cases'!$E$2:$E$106,"*"&$C28&"*",'Test Cases'!$B$2:$B$106,"Postman (API)") -> 1 | K28: =COUNTIFS('Test Cases'!$E$2:$E$106,"*"&$C28&"*",'Test Cases'!$B$2:$B$106,"SQL (DB)") -> 1 | L28: =COUNTIFS('Test Cases'!$E$2:$E$106,"*"&$C28&"*",'Test Cases'!$B$2:$B$106,"E2E") -> 1 | M28: =SUM(I28:L28) -> 4 | N28: =IF(M28=0,"NOT COVERED","Covered") -> Covered | O28: =COUNTIFS('Test Cases'!$E$2:$E$106,"*"&$C28&"*",'Test Cases'!$O$2:$O$106,"Pass") -> 0 | P28: =COUNTIFS('Test Cases'!$E$2:$E$106,"*"&$C28&"*",'Test Cases'!$O$2:$O$106,"Fail") -> 0 | Q28: =IF(M28=0,"-",IF(P28>0,"FAIL",IF(O28=M28,"PASS",IF(O28=0,"NOT RUN","IN PROGRESS")))) -> NOT RUN | T28: Tracking status flow logs + SMS/Email notification logs
A29: FR-005 | B29: Returns & Refunds Processing | C29: FR-005-AC1 | D29: Return window enforcement (30 days) | E29: UI-RE001, UI-RE002 | F29: API-RE001, API-RE004 | H29: E2E-RE001 | I29: =COUNTIFS('Test Cases'!$E$2:$E$106,"*"&$C29&"*",'Test Cases'!$B$2:$B$106,"Cypress (UI)") -> 2 | J29: =COUNTIFS('Test Cases'!$E$2:$E$106,"*"&$C29&"*",'Test Cases'!$B$2:$B$106,"Postman (API)") -> 2 | K29: =COUNTIFS('Test Cases'!$E$2:$E$106,"*"&$C29&"*",'Test Cases'!$B$2:$B$106,"SQL (DB)") -> 0 | L29: =COUNTIFS('Test Cases'!$E$2:$E$106,"*"&$C29&"*",'Test Cases'!$B$2:$B$106,"E2E") -> 1 | M29: =SUM(I29:L29) -> 5 | N29: =IF(M29=0,"NOT COVERED","Covered") -> Covered | O29: =COUNTIFS('Test Cases'!$E$2:$E$106,"*"&$C29&"*",'Test Cases'!$O$2:$O$106,"Pass") -> 0 | P29: =COUNTIFS('Test Cases'!$E$2:$E$106,"*"&$C29&"*",'Test Cases'!$O$2:$O$106,"Fail") -> 0 | Q29: =IF(M29=0,"-",IF(P29>0,"FAIL",IF(O29=M29,"PASS",IF(O29=0,"NOT RUN","IN PROGRESS")))) -> NOT RUN | T29: Return workflow logs + Stock restoration SQL validation
A30: FR-005 | B30: Returns & Refunds Processing | C30: FR-005-AC2 | D30: Refund amount calculated correctly | E30: UI-RE003 | F30: API-RE002, API-RE004 | H30: E2E-RE001 | I30: =COUNTIFS('Test Cases'!$E$2:$E$106,"*"&$C30&"*",'Test Cases'!$B$2:$B$106,"Cypress (UI)") -> 1 | J30: =COUNTIFS('Test Cases'!$E$2:$E$106,"*"&$C30&"*",'Test Cases'!$B$2:$B$106,"Postman (API)") -> 2 | K30: =COUNTIFS('Test Cases'!$E$2:$E$106,"*"&$C30&"*",'Test Cases'!$B$2:$B$106,"SQL (DB)") -> 0 | L30: =COUNTIFS('Test Cases'!$E$2:$E$106,"*"&$C30&"*",'Test Cases'!$B$2:$B$106,"E2E") -> 1 | M30: =SUM(I30:L30) -> 4 | N30: =IF(M30=0,"NOT COVERED","Covered") -> Covered | O30: =COUNTIFS('Test Cases'!$E$2:$E$106,"*"&$C30&"*",'Test Cases'!$O$2:$O$106,"Pass") -> 0 | P30: =COUNTIFS('Test Cases'!$E$2:$E$106,"*"&$C30&"*",'Test Cases'!$O$2:$O$106,"Fail") -> 0 | Q30: =IF(M30=0,"-",IF(P30>0,"FAIL",IF(O30=M30,"PASS",IF(O30=0,"NOT RUN","IN PROGRESS")))) -> NOT RUN | T30: Return workflow logs + Stock restoration SQL validation
A31: FR-005 | B31: Returns & Refunds Processing | C31: FR-005-AC3 | D31: Refund issued to original payment method | E31: UI-RE004 | F31: API-RE003 | G31: DB-PAY-004 | H31: E2E-RE001 | I31: =COUNTIFS('Test Cases'!$E$2:$E$106,"*"&$C31&"*",'Test Cases'!$B$2:$B$106,"Cypress (UI)") -> 1 | J31: =COUNTIFS('Test Cases'!$E$2:$E$106,"*"&$C31&"*",'Test Cases'!$B$2:$B$106,"Postman (API)") -> 1 | K31: =COUNTIFS('Test Cases'!$E$2:$E$106,"*"&$C31&"*",'Test Cases'!$B$2:$B$106,"SQL (DB)") -> 1 | L31: =COUNTIFS('Test Cases'!$E$2:$E$106,"*"&$C31&"*",'Test Cases'!$B$2:$B$106,"E2E") -> 1 | M31: =SUM(I31:L31) -> 4 | N31: =IF(M31=0,"NOT COVERED","Covered") -> Covered | O31: =COUNTIFS('Test Cases'!$E$2:$E$106,"*"&$C31&"*",'Test Cases'!$O$2:$O$106,"Pass") -> 0 | P31: =COUNTIFS('Test Cases'!$E$2:$E$106,"*"&$C31&"*",'Test Cases'!$O$2:$O$106,"Fail") -> 0 | Q31: =IF(M31=0,"-",IF(P31>0,"FAIL",IF(O31=M31,"PASS",IF(O31=0,"NOT RUN","IN PROGRESS")))) -> NOT RUN | T31: Return workflow logs + Stock restoration SQL validation
A32: FR-005 | B32: Returns & Refunds Processing | C32: FR-005-AC4 | D32: Inventory restored upon return receipt | G32: DB-INV-004 | H32: E2E-RE001, E2E-INV-001 | I32: =COUNTIFS('Test Cases'!$E$2:$E$106,"*"&$C32&"*",'Test Cases'!$B$2:$B$106,"Cypress (UI)") -> 0 | J32: =COUNTIFS('Test Cases'!$E$2:$E$106,"*"&$C32&"*",'Test Cases'!$B$2:$B$106,"Postman (API)") -> 0 | K32: =COUNTIFS('Test Cases'!$E$2:$E$106,"*"&$C32&"*",'Test Cases'!$B$2:$B$106,"SQL (DB)") -> 1 | L32: =COUNTIFS('Test Cases'!$E$2:$E$106,"*"&$C32&"*",'Test Cases'!$B$2:$B$106,"E2E") -> 2 | M32: =SUM(I32:L32) -> 3 | N32: =IF(M32=0,"NOT COVERED","Covered") -> Covered | O32: =COUNTIFS('Test Cases'!$E$2:$E$106,"*"&$C32&"*",'Test Cases'!$O$2:$O$106,"Pass") -> 0 | P32: =COUNTIFS('Test Cases'!$E$2:$E$106,"*"&$C32&"*",'Test Cases'!$O$2:$O$106,"Fail") -> 0 | Q32: =IF(M32=0,"-",IF(P32>0,"FAIL",IF(O32=M32,"PASS",IF(O32=0,"NOT RUN","IN PROGRESS")))) -> NOT RUN | T32: Return workflow logs + Stock restoration SQL validation
A33: FR-005 | B33: Returns & Refunds Processing | C33: FR-005-AC5 | D33: Audit trail completeness | G33: DB-AUD-001, DB-AUD-002 | H33: E2E-RE001 | I33: =COUNTIFS('Test Cases'!$E$2:$E$106,"*"&$C33&"*",'Test Cases'!$B$2:$B$106,"Cypress (UI)") -> 0 | J33: =COUNTIFS('Test Cases'!$E$2:$E$106,"*"&$C33&"*",'Test Cases'!$B$2:$B$106,"Postman (API)") -> 0 | K33: =COUNTIFS('Test Cases'!$E$2:$E$106,"*"&$C33&"*",'Test Cases'!$B$2:$B$106,"SQL (DB)") -> 2 | L33: =COUNTIFS('Test Cases'!$E$2:$E$106,"*"&$C33&"*",'Test Cases'!$B$2:$B$106,"E2E") -> 1 | M33: =SUM(I33:L33) -> 3 | N33: =IF(M33=0,"NOT COVERED","Covered") -> Covered | O33: =COUNTIFS('Test Cases'!$E$2:$E$106,"*"&$C33&"*",'Test Cases'!$O$2:$O$106,"Pass") -> 0 | P33: =COUNTIFS('Test Cases'!$E$2:$E$106,"*"&$C33&"*",'Test Cases'!$O$2:$O$106,"Fail") -> 0 | Q33: =IF(M33=0,"-",IF(P33>0,"FAIL",IF(O33=M33,"PASS",IF(O33=0,"NOT RUN","IN PROGRESS")))) -> NOT RUN | T33: Return workflow logs + Stock restoration SQL validation
